[2023-07-12T11:10:58.288+0000] {taskinstance.py:1087} INFO - Dependencies all met for <TaskInstance: create_table.create_table manual__2023-07-12T11:05:44.948854+00:00 [queued]>
[2023-07-12T11:10:58.302+0000] {taskinstance.py:1087} INFO - Dependencies all met for <TaskInstance: create_table.create_table manual__2023-07-12T11:05:44.948854+00:00 [queued]>
[2023-07-12T11:10:58.303+0000] {taskinstance.py:1283} INFO - 
--------------------------------------------------------------------------------
[2023-07-12T11:10:58.305+0000] {taskinstance.py:1284} INFO - Starting attempt 2 of 2
[2023-07-12T11:10:58.306+0000] {taskinstance.py:1285} INFO - 
--------------------------------------------------------------------------------
[2023-07-12T11:10:58.330+0000] {taskinstance.py:1304} INFO - Executing <Task(SnowflakeOperator): create_table> on 2023-07-12 11:05:44.948854+00:00
[2023-07-12T11:10:58.340+0000] {standard_task_runner.py:55} INFO - Started process 2341 to run task
[2023-07-12T11:10:58.346+0000] {standard_task_runner.py:82} INFO - Running: ['***', 'tasks', 'run', 'create_table', 'create_table', 'manual__2023-07-12T11:05:44.948854+00:00', '--job-id', '5', '--raw', '--subdir', 'DAGS_FOLDER/3.py', '--cfg-path', '/tmp/tmp8y4ideca']
[2023-07-12T11:10:58.351+0000] {standard_task_runner.py:83} INFO - Job 5: Subtask create_table
[2023-07-12T11:10:58.442+0000] {task_command.py:389} INFO - Running <TaskInstance: create_table.create_table manual__2023-07-12T11:05:44.948854+00:00 [running]> on host 38053bc535fb
[2023-07-12T11:10:58.540+0000] {taskinstance.py:1513} INFO - Exporting the following env vars:
AIRFLOW_CTX_DAG_OWNER=***
AIRFLOW_CTX_DAG_ID=create_table
AIRFLOW_CTX_TASK_ID=create_table
AIRFLOW_CTX_EXECUTION_DATE=2023-07-12T11:05:44.948854+00:00
AIRFLOW_CTX_TRY_NUMBER=2
AIRFLOW_CTX_DAG_RUN_ID=manual__2023-07-12T11:05:44.948854+00:00
[2023-07-12T11:10:58.542+0000] {sql.py:253} INFO - Executing: 
CREATE OR REPLACE TABLE my_table (
    id INT,
    name VARCHAR,
    age INT
);
[2023-07-12T11:10:58.561+0000] {base.py:73} INFO - Using connection ID 'snowflake_connection' for task execution.
[2023-07-12T11:10:59.598+0000] {logging_mixin.py:137} WARNING - /home/***/.local/lib/python3.7/site-packages/snowflake/connector/options.py:109 UserWarning: You have an incompatible version of 'pyarrow' installed (9.0.0), please install a version that adheres to: 'pyarrow<10.1.0,>=10.0.1; extra == "pandas"'
[2023-07-12T11:10:59.696+0000] {base.py:73} INFO - Using connection ID 'snowflake_connection' for task execution.
[2023-07-12T11:10:59.699+0000] {connection.py:300} INFO - Snowflake Connector for Python Version: 3.0.4, Python Version: 3.7.15, Platform: Linux-5.15.49-linuxkit-x86_64-with-debian-11.5
[2023-07-12T11:10:59.701+0000] {connection.py:1013} INFO - This connection is in OCSP Fail Open Mode. TLS Certificates would be checked for validity and revocation status. Any other Certificate Revocation related exceptions or OCSP Responder failures would be disregarded in favor of connectivity.
[2023-07-12T11:10:59.702+0000] {connection.py:1023} INFO - THIS CONNECTION IS IN INSECURE MODE. IT MEANS THE CERTIFICATE WILL BE VALIDATED BUT THE CERTIFICATE REVOCATION STATUS WILL NOT BE CHECKED.
[2023-07-12T11:10:59.703+0000] {connection.py:1030} INFO - Setting use_openssl_only mode to False
[2023-07-12T11:11:18.493+0000] {local_task_job.py:224} WARNING - State of this instance has been externally set to restarting. Terminating instance.
[2023-07-12T11:11:18.499+0000] {process_utils.py:133} INFO - Sending Signals.SIGTERM to group 2341. PIDs of all processes in the group: [2341]
[2023-07-12T11:11:18.500+0000] {process_utils.py:84} INFO - Sending the signal Signals.SIGTERM to group 2341
[2023-07-12T11:11:18.502+0000] {taskinstance.py:1483} ERROR - Received SIGTERM. Terminating subprocesses.
[2023-07-12T11:11:18.519+0000] {taskinstance.py:1772} ERROR - Task failed with exception
Traceback (most recent call last):
  File "/home/airflow/.local/lib/python3.7/site-packages/airflow/providers/common/sql/operators/sql.py", line 261, in execute
    return_last=self.return_last,
  File "/home/airflow/.local/lib/python3.7/site-packages/airflow/providers/snowflake/hooks/snowflake.py", line 373, in run
    with closing(self.get_conn()) as conn:
  File "/home/airflow/.local/lib/python3.7/site-packages/airflow/providers/snowflake/hooks/snowflake.py", line 296, in get_conn
    conn = connector.connect(**conn_config)
  File "/home/airflow/.local/lib/python3.7/site-packages/snowflake/connector/__init__.py", line 51, in Connect
    return SnowflakeConnection(**kwargs)
  File "/home/airflow/.local/lib/python3.7/site-packages/snowflake/connector/connection.py", line 319, in __init__
    self.connect(**kwargs)
  File "/home/airflow/.local/lib/python3.7/site-packages/snowflake/connector/connection.py", line 590, in connect
    self.__open_connection()
  File "/home/airflow/.local/lib/python3.7/site-packages/snowflake/connector/connection.py", line 860, in __open_connection
    self.authenticate_with_retry(self.auth_class)
  File "/home/airflow/.local/lib/python3.7/site-packages/snowflake/connector/connection.py", line 1127, in authenticate_with_retry
    self._authenticate(auth_instance)
  File "/home/airflow/.local/lib/python3.7/site-packages/snowflake/connector/connection.py", line 1165, in _authenticate
    session_parameters=self._session_parameters,
  File "/home/airflow/.local/lib/python3.7/site-packages/snowflake/connector/auth/_auth.py", line 255, in authenticate
    socket_timeout=auth_timeout,
  File "/home/airflow/.local/lib/python3.7/site-packages/snowflake/connector/network.py", line 729, in _post_request
    _include_retry_params=_include_retry_params,
  File "/home/airflow/.local/lib/python3.7/site-packages/snowflake/connector/network.py", line 819, in fetch
    session, method, full_url, headers, data, retry_ctx, **kwargs
  File "/home/airflow/.local/lib/python3.7/site-packages/snowflake/connector/network.py", line 941, in _request_exec_wrapper
    raise e
  File "/home/airflow/.local/lib/python3.7/site-packages/snowflake/connector/network.py", line 868, in _request_exec_wrapper
    **kwargs,
  File "/home/airflow/.local/lib/python3.7/site-packages/snowflake/connector/network.py", line 1138, in _request_exec
    raise err
  File "/home/airflow/.local/lib/python3.7/site-packages/snowflake/connector/network.py", line 1045, in _request_exec
    auth=SnowflakeAuth(token),
  File "/home/airflow/.local/lib/python3.7/site-packages/snowflake/connector/vendored/requests/sessions.py", line 587, in request
    resp = self.send(prep, **send_kwargs)
  File "/home/airflow/.local/lib/python3.7/site-packages/snowflake/connector/vendored/requests/sessions.py", line 701, in send
    r = adapter.send(request, **kwargs)
  File "/home/airflow/.local/lib/python3.7/site-packages/snowflake/connector/vendored/requests/adapters.py", line 498, in send
    chunked=chunked,
  File "/home/airflow/.local/lib/python3.7/site-packages/snowflake/connector/vendored/urllib3/connectionpool.py", line 710, in urlopen
    chunked=chunked,
  File "/home/airflow/.local/lib/python3.7/site-packages/snowflake/connector/vendored/urllib3/connectionpool.py", line 386, in _make_request
    self._validate_conn(conn)
  File "/home/airflow/.local/lib/python3.7/site-packages/snowflake/connector/vendored/urllib3/connectionpool.py", line 1042, in _validate_conn
    conn.connect()
  File "/home/airflow/.local/lib/python3.7/site-packages/snowflake/connector/vendored/urllib3/connection.py", line 363, in connect
    self.sock = conn = self._new_conn()
  File "/home/airflow/.local/lib/python3.7/site-packages/snowflake/connector/vendored/urllib3/connection.py", line 175, in _new_conn
    (self._dns_host, self.port), self.timeout, **extra_kw
  File "/home/airflow/.local/lib/python3.7/site-packages/snowflake/connector/vendored/urllib3/util/connection.py", line 85, in create_connection
    sock.connect(sa)
  File "/home/airflow/.local/lib/python3.7/site-packages/airflow/models/taskinstance.py", line 1485, in signal_handler
    raise AirflowException("Task received SIGTERM signal")
airflow.exceptions.AirflowException: Task received SIGTERM signal
[2023-07-12T11:11:18.529+0000] {taskinstance.py:1327} INFO - Marking task as UP_FOR_RETRY. dag_id=create_table, task_id=create_table, execution_date=20230712T110544, start_date=20230712T111058, end_date=20230712T111118
[2023-07-12T11:11:18.547+0000] {standard_task_runner.py:105} ERROR - Failed to execute job 5 for task create_table (Task received SIGTERM signal; 2341)
[2023-07-12T11:11:18.595+0000] {process_utils.py:79} INFO - Process psutil.Process(pid=2341, status='terminated', exitcode=1, started='11:10:58') (2341) terminated with exit code 1
